Workbook

Sheet Cover
B2: UK Electricity Generation & Capacity Factor Dataset
B3: Quarterly, 2000 - present, all generating companies
B5: WORKBOOK STRUCTURE
B6: 1. Cover (this sheet) - sources, methodology, notes 2. Generation (TWh) - quarterly electricity generated by fuel/technology, Q1 2000-present 3. Capacity (MW) - installed nameplate capacity by fuel/technology, Q1 2000-present 4. Capacity Factor (%) - live formula: Generation / Capacity / hours in quarter
B8: GENERATION - PRIMARY SOURCE
B9: DESNZ, Energy Trends Table 5.1 (quarterly). File: ET_5_1_JUN_26.xlsx, published 30 June 2026. Sheet "Quarter", Table 5.1b "Electricity generated by fuel (TWh)", "All generating companies" rows. Covers Q1 2000 to Q1 2026 (Q1 2026 provisional). https://www.gov.uk/government/statistics/electricity-section-5-energy-trends
B11: GENERATION - RENEWABLES BACKFILL, 2000-2009
B12: DESNZ, DUKES Table 6.2 "Capacity of, and electricity generated from, renewable sources". File: DUKES_6_2.xlsx, published 31 July 2025, annual data 1990-2024. ET 5.1 only separately reports Onshore wind, Offshore wind, Solar and Shoreline wave/tidal from Q1 2010 onward. DUKES 6.2 has annual generation figures for all four back to 1990, used to backfill 2000-2009: each annual GWh figure was converted to TWh and divided evenly by 4 across that year's quarters (a simplification, not a seasonal estimate - see the Generation sheet's yellow-highlighted cells and the genuine 2010 data for comparison). Validated against ET 5.1 at the 2010 boundary for all four series (each matched within rounding).
B14: CAPACITY - SOURCES AND AN IMPORTANT CORRECTION
B15: Coal, Oil, Gas, Nuclear, Pumped storage and Other fuels capacity: DESNZ DUKES Table 5.7 "Plant capacity: United Kingdom", "All generating companies" rows, annual 1996-2024. Onshore wind, Offshore wind, Solar, Shoreline wave/tidal and Hydro capacity: DESNZ DUKES Table 6.2 "Installed Capacity" table, annual 1990-2024 - NOT Table 5.7. Why two different sources for capacity: DUKES 5.7 is explicitly a DE-RATED capacity table (its own cover sheet states wind, solar and small-scale hydro capacity are de-rated for intermittency, by factors of 0.43, 0.17 and 0.365 respectively - DUKES 5.7 Note 4). This is correct for DESNZ's own purpose (grid security/adequacy planning) but WRONG as a denominator for capacity factor, which needs true nameplate capacity. Using DUKES 5.7's de-rated wind/solar figures initially produced impossible capacity factors above 100% (offshore wind exceeded 100% in numerous winter quarters; the de-rating factors of 0.43 and 0.17 line up almost exactly with the resulting error ratios). DUKES 6.2's "Installed Capacity" table is NOT de-rated and gives genuine nameplate MW, confirmed by cross-checking 2024 offshore wind (15,836 MW here) against independently reported UK offshore wind capacity (~16 GW) - a match. Coal/Oil/Gas/Nuclear are not de-rated in DUKES 5.7 (de-rating only applies to wind/solar/small-hydro per Note 4), so those remain sourced from Table 5.7 as before.
B17: CAPACITY - 2025/2026 FORWARD-FILL
B18: Both DUKES 5.7 and 6.2's most recent year is 2024 (2025 data publishes July 2026, after this workbook was built). Capacity for 2025 and Q1 2026 has been forward-filled from the 2024 figure and is flagged in the "capacity forward filled" column on the Capacity sheet. This will understate true capacity for any technology that grew significantly in 2025 (notably offshore wind) - treat 2025/2026 capacity factor figures with more caution than earlier years until this is updated with real DUKES 2025 data.
... B39: • SPIKE: Q4 2021 shows an unusually large total cost (£697m, driven mainly by a £627m thermal constraint figure) - flagged red on the Curtailment sheet rather than smoothed or treated as an error. Plausibly linked to a significant grid event in that period (e.g. the North Sea Link/IFA interconnector and transmission issues around that time); not independently verified against news reporting as part of this workbook. • Data starts Q2 2017 (1 April 2017) - does not extend back to 2000 like the rest of the workbook. Only compare against the Generation/Capacity/Capacity Factor sheets for the overlapping window (2017-2026). • This is total constraint cost, not solely payments to wind farms - includes compensation paid to replacement generation (mostly gas) as well as the curtailed generator itself. • Q1 2026 capacity/generation figures elsewhere in this workbook are provisional/forward-filled; bear this in mind if comparing the very latest quarter across sheets.

Sheet Generation (TWh)
A1: UK Electricity Generation by Fuel (TWh) - Quarterly, All Generating Companies
A2: Source: DESNZ Energy Trends Table 5.1 (2010+ splits); DUKES Table 6.2 backfill (2000-2009, wind/solar/marine). See Cover sheet.
A4: Year | B4: Quarter | C4: Provisional | D4: Coal | E4: Oil | F4: Gas | G4: Nuclear | H4: Hydro (natural flow) | I4: Onshore wind | J4: Offshore wind | K4: Shoreline wave / tidal | L4: Solar | M4: Bioenergy | N4: Other fuels | O4: Pumped storage | P4: Battery storage | Q4: Total all generating companies | R4: Onshore wind backfilled | S4: Offshore wind backfilled | T4: Solar backfilled | U4: Marine backfilled
A5: 2000 | B5: 1 | C5: =FALSE() | D5: 32.5625 | E5: 1.8032 | F5: 40.8957 | G5: 22.9725 | H5: 2.1272 | I5: 0.2362 | J5: 0.0002 | K5: 0 | L5: 0.0003 | M5: 1.0836 | N5: 1.116 | O5: 0.6954 | P5: [x] | Q5: 103.4814 | R5: =TRUE() | S5: =TRUE() | T5: =TRUE() | U5: =TRUE()
A6: 2000 | B6: 2 | C6: =FALSE() | D6: 26.5675 | E6: 1.5093 | F6: 35.4085 | G6: 21.073 | H6: 0.6813 | I6: 0.2362 | J6: 0.0002 | K6: 0 | L6: 0.0003 | M6: 1.017 | N6: 1.3754 | O6: 0.6437 | P6: [x] | Q6: 88.5067 | R6: =TRUE() | S6: =TRUE() | T6: =TRUE() | U6: =TRUE()
A7: 2000 | B7: 3 | C7: =FALSE() | D7: 25.3221 | E7: 1.4077 | F7: 34.7805 | G7: 19.7057 | H7: 0.5747 | I7: 0.2362 | J7: 0.0002 | K7: 0 | L7: 0.0003 | M7: 1.1123 | N7: 0.7226 | O7: 0.6319 | P7: [x] | Q7: 84.5007 | R7: =TRUE() | S7: =TRUE() | T7: =TRUE() | U7: =TRUE()
A8: 2000 | B8: 4 | C8: =FALSE() | D8: 35.4977 | E8: 1.8039 | F8: 36.9919 | G8: 21.3116 | H8: 1.7025 | I8: 0.2362 | J8: 0.0002 | K8: 0 | L8: 0.0003 | M8: 1.1152 | N8: 1.187 | O8: 0.7234 | P8: [x] | Q8: 100.5805 | R8: =TRUE() | S8: =TRUE() | T8: =TRUE() | U8: =TRUE()
A9: 2001 | B9: 1 | C9: =FALSE() | D9: 41.0145 | E9: 1.9467 | F9: 37.4734 | G9: 22.7801 | H9: 1.0382 | I9: 0.24 | J9: 0.0012 | K9: 0 | L9: 0.0005 | M9: 1.163 | N9: 0.9424 | O9: 0.6815 | P9: [x] | Q9: 107.2868 | R9: =TRUE() | S9: =TRUE() | T9: =TRUE() | U9: =TRUE()
A10: 2001 | B10: 2 | C10: =FALSE() | D10: 29.1334 | E10: 1.3971 | F10: 35.9075 | G10: 20.1834 | H10: 0.5784 | I10: 0.24 | J10: 0.0012 | K10: 0 | L10: 0.0005 | M10: 1.2253 | N10: 0.9043 | O10: 0.368 | P10: [x] | Q10: 89.9326 | R10: =TRUE() | S10: =TRUE() | T10: =TRUE() | U10: =TRUE()
A11: 2001 | B11: 3 | C11: =FALSE() | D11: 26.0037 | E11: 0.7744 | F11: 32.9445 | G11: 22.3834 | H11: 0.6334 | I11: 0.24 | J11: 0.0012 | K11: 0 | L11: 0.0005 | M11: 1.3153 | N11: 0.8752 | O11: 0.5732 | P11: [x] | Q11: 85.7363 | R11: =TRUE() | S11: =TRUE() | T11: =TRUE() | U11: =TRUE()
A12: 2001 | B12: 4 | C12: =FALSE() | D12: 35.3089 | E12: 1.135 | F12: 35.5806 | G12: 24.7457 | H12: 1.8046 | I12: 0.24 | J12: 0.0012 | K12: 0 | L12: 0.0005 | M12: 1.3438 | N12: 0.8551 | O12: 0.7993 | P12: [x] | Q12: 101.823 | R12: =TRUE() | S12: =TRUE() | T12: =TRUE() | U12: =TRUE()
A13: 2002 | B13: 1 | C13: =FALSE() | D13: 37.3564 | E13: 1.1829 | F13: 38.2859 | G13: 24.5499 | H13: 1.972 | I13: 0.3128 | J13: 0.0012 | K13: 0 | L13: 0.0007 | M13: 1.4296 | N13: 0.9178 | O13: 0.7381 | P13: [x] | Q13: 106.6832 | R13: =TRUE() | S13: =TRUE() | T13: =TRUE() | U13: =TRUE()
A14: 2002 | B14: 2 | C14: =FALSE() | D14: 24.2773 | E14: 0.9207 | F14: 38.7051 | G14: 21.5497 | H14: 1.1367 | I14: 0.3128 | J14: 0.0012 | K14: 0 | L14: 0.0007 | M14: 1.3653 | N14: 0.8639 | O14: 0.59 | P14: [x] | Q14: 89.6843 | R14: =TRUE() | S14: =TRUE() | T14: =TRUE() | U14: =TRUE()
A15: 2002 | B15: 3 | C15: =FALSE() | D15: 24.8788 | E15: 1.1447 | F15: 37.8918 | G15: 20.6235 | H15: 0.6523 | I15: 0.3128 | J15: 0.0012 | K15: 0 | L15: 0.0007 | M15: 1.3888 | N15: 0.9453 | O15: 0.638 | P15: [x] | Q15: 88.4951 | R15: =TRUE() | S15: =TRUE() | T15: =TRUE() | U15: =TRUE()
A16: 2002 | B16: 4 | C16: =FALSE() | D16: 37.7661 | E16: 1.5506 | F16: 37.3947 | G16: 21.1253 | H16: 1.0265 | I16: 0.3128 | J16: 0.0012 | K16: 0 | L16: 0.0007 | M16: 1.4416 | N16: 0.992 | O16: 0.6856 | P16: [x] | Q16: 102.3833 | R16: =TRUE() | S16: =TRUE() | T16: =TRUE() | U16: =TRUE()
... A44: 2009 | B44: 4 | C44: =FALSE() | D44: 26.6726 | E44: 1.5756 | F44: 46.8173 | G44: 16.3041 | H44: 1.6101 | I44: 1.8823 | J44: 0.4385 | K44: 0.0002 | L44: 0.005 | M44: 2.8653 | N44: 0.7807 | O44: 0.9136 | P44: [x] | Q44: 100.1348 | R44: =TRUE() | S44: =TRUE() | T44: =TRUE() | U44: =TRUE()
A45: 2010 | B45: 1 | C45: =FALSE() | D45: 32.6166 | E45: 1.4378 | F45: 48.1857 | G45: 18.1902 | H45: 0.8449 | I45: 1.7574 | J45: 0.6709 | K45: 0.0005 | L45: 0.0057 | M45: 2.9693 | N45: 0.6398 | O45: 0.8647 | P45: [x] | Q45: 108.1833 | R45: =FALSE() | S45: =FALSE() | T45: =FALSE() | U45: =FALSE()
A46: 2010 | B46: 2 | C46: =FALSE() | D46: 19.5307 | E46: 0.9248 | F46: 45.4867 | G46: 13.8797 | H46: 0.6525 | I46: 1.1985 | J46: 0.4604 | K46: 0.0006 | L46: 0.0112 | M46: 2.9286 | N46: 0.6703 | O46: 0.7627 | P46: [x] | Q46: 86.5067 | R46: =FALSE() | S46: =FALSE() | T46: =FALSE() | U46: =FALSE()
A47: 2010 | B47: 3 | C47: =FALSE() | D47: 19.7906 | E47: 1.1368 | F47: 40.83 | G47: 13.0171 | H47: 0.8557 | I47: 1.9337 | J47: 0.8257 | K47: 0.0006 | L47: 0.0145 | M47: 3.1264 | N47: 0.6416 | O47: 0.705 | P47: [x] | Q47: 82.8777 | R47: =FALSE() | S47: =FALSE() | T47: =FALSE() | U47: =FALSE()
A48: 2010 | B48: 4 | C48: =FALSE() | D48: 35.6563 | E48: 1.3061 | F48: 41.1511 | G48: 17.0527 | H48: 1.2383 | I48: 2.3364 | J48: 1.1027 | K48: 0.0001 | L48: 0.0089 | M48: 3.237 | N48: 0.593 | O48: 0.8181 | P48: [x] | Q48: 104.5006 | R48: =FALSE() | S48: =FALSE() | T48: =FALSE() | U48: =FALSE()
A49: 2011 | B49: 1 | C49: =FALSE() | D49: 35.1264 | E49: 0.9069 | F49: 38.3009 | G49: 19.4516 | H49: 1.3037 | I49: 2.3966 | J49: 0.9981 | K49: 0.0002 | L49: 0.0153 | M49: 3.3614 | N49: 0.7384 | O49: 0.7704 | P49: [x] | Q49: 103.3699 | R49: =FALSE() | S49: =FALSE() | T49: =FALSE() | U49: =FALSE()
A50: 2011 | B50: 2 | C50: =FALSE() | D50: 19.041 | E50: 0.5614 | F50: 36.9241 | G50: 19.1546 | H50: 1.1416 | I50: 2.4922 | J50: 1.1286 | K50: 0.0003 | L50: 0.0661 | M50: 3.1551 | N50: 0.7477 | O50: 0.6536 | P50: [x] | Q50: 85.0663 | R50: =FALSE() | S50: =FALSE() | T50: =FALSE() | U50: =FALSE()
A51: 2011 | B51: 3 | C51: =FALSE() | D51: 19.0959 | E51: 0.7718 | F51: 38.6148 | G51: 15.7581 | H51: 1.2313 | I51: 1.9148 | J51: 1.0985 | K51: 0.0002 | L51: 0.1052 | M51: 3.3483 | N51: 0.779 | O51: 0.7019 | P51: [x] | Q51: 83.4199 | R51: =FALSE() | S51: =FALSE() | T51: =FALSE() | U51: =FALSE()
A52: 2011 | B52: 4 | C52: =FALSE() | D52: 35.179 | E52: 0.8788 | F52: 32.6591 | G52: 14.6161 | H52: 2.0152 | I52: 4.0104 | J52: 1.9239 | K52: 0.0002 | L52: 0.0571 | M52: 3.448 | N52: 0.5583 | O52: 0.7796 | P52: [x] | Q52: 96.1258 | R52: =FALSE() | S52: =FALSE() | T52: =FALSE() | U52: =FALSE()
A53: 2012 | B53: 1 | C53: =FALSE() | D53: 42.0411 | E53: 0.8557 | F53: 27.226 | G53: 17.1989 | H53: 1.8251 | I53: 3.5652 | J53: 1.507 | K53: 0.001 | L53: 0.1782 | M53: 3.9257 | N53: 0.7812 | O53: 0.794 | P53: [x] | Q53: 99.8991 | R53: =FALSE() | S53: =FALSE() | T53: =FALSE() | U53: =FALSE()
A54: 2012 | B54: 2 | C54: =FALSE() | D54: 31.2252 | E54: 0.6726 | F54: 25.2327 | G54: 18.5256 | H54: 0.7955 | I54: 2.242 | J54: 1.6499 | K54: 0.0009 | L54: 0.4378 | M54: 3.0077 | N54: 0.8634 | O54: 0.6747 | P54: [x] | Q54: 85.328 | R54: =FALSE() | S54: =FALSE() | T54: =FALSE() | U54: =FALSE()
A55: 2012 | B55: 3 | C55: =FALSE() | D55: 28.7731 | E55: 0.563 | F55: 22.9812 | G55: 18.0309 | H55: 1.0535 | I55: 2.6475 | J55: 1.7074 | K55: 0.0012 | L55: 0.5541 | M55: 3.5445 | N55: 0.878 | O55: 0.7051 | P55: [x] | Q55: 81.4396 | R55: =FALSE() | S55: =FALSE() | T55: =FALSE() | U55: =FALSE()
A56: 2012 | B56: 4 | C56: =FALSE() | D56: 40.7526 | E56: 0.8 | F56: 24.7296 | G56: 16.6496 | H56: 1.635 | I56: 3.7892 | J56: 2.7387 | K56: 0.0012 | L56: 0.1836 | M56: 4.2559 | N56: 0.878 | O56: 0.7927 | P56: [x] | Q56: 97.2063 | R56: =FALSE() | S56: =FALSE() | T56: =FALSE() | U56: =FALSE()
... A72: 2016 | B72: 4 | C72: =FALSE() | D72: 8.6899 | E72: 0.5376 | F72: 42.0952 | G72: 18.8722 | H72: 1.2083 | I72: 5.873 | J72: 4.4234 | K72: 0 | L72: 1.3305 | M72: 7.6069 | N72: 1.5336 | O72: 0.8152 | P72: [x] | Q72: 92.9856 | R72: =FALSE() | S72: =FALSE() | T72: =FALSE() | U72: =FALSE()
A73: 2017 | B73: 1 | C73: =FALSE() | D73: 10.4297 | E73: 0.372 | F73: 37.8503 | G73: 17.6441 | H73: 1.7984 | I73: 5.1653 | J73: 2.6437 | K73: 0.0003 | L73: 1.1882 | M73: 8.9658 | N73: 1.285 | O73: 0.7913 | P73: 0 | Q73: 93.2325 | R73: =FALSE() | S73: =FALSE() | T73: =FALSE() | U73: =FALSE()
A74: 2017 | B74: 2 | C74: =FALSE() | D74: 1.5393 | E74: 0.3585 | F74: 31.7795 | G74: 17.8324 | H74: 0.8639 | I74: 3.8616 | J74: 1.9941 | K74: 0.0001 | L74: 3.3979 | M74: 7.8263 | N74: 1.2989 | O74: 0.6935 | P74: 0 | Q74: 75.7679 | R74: =FALSE() | S74: =FALSE() | T74: =FALSE() | U74: =FALSE()
A75: 2017 | B75: 3 | C75: =FALSE() | D75: 2.1612 | E75: 0.4586 | F75: 30.1398 | G75: 18.172 | H75: 1.2638 | I75: 6.3762 | J75: 4.0418 | K75: 0.0024 | L75: 2.927 | M75: 7.7654 | N75: 1.2994 | O75: 0.6364 | P75: 0 | Q75: 74.4151 | R75: =FALSE() | S75: =FALSE() | T75: =FALSE() | U75: =FALSE()
A76: 2017 | B76: 4 | C76: =FALSE() | D76: 8.4002 | E76: 0.4254 | F76: 36.9763 | G76: 16.6878 | H76: 1.9557 | I76: 7.633 | J76: 4.3942 | K76: 0.0013 | L76: 0.9664 | M76: 7.3368 | N76: 1.3362 | O76: 0.7509 | P76: 0.0005 | Q76: 91.8044 | R76: =FALSE() | S76: =FALSE() | T76: =FALSE() | U76: =FALSE()
A77: 2018 | B77: 1 | C77: =FALSE() | D77: 8.7119 | E77: 0.4875 | F77: 36.9017 | G77: 16.6444 | H77: 1.5645 | I77: 9.5614 | J77: 7.927 | K77: 0.0031 | L77: 1.7931 | M77: 7.7762 | N77: 1.6 | O77: 0.7456 | P77: 0.0035 | Q77: 93.7199 | R77: =FALSE() | S77: =FALSE() | T77: =FALSE() | U77: =FALSE()
A78: 2018 | B78: 2 | C78: =FALSE() | D78: 1.2096 | E78: 0.292 | F78: 32.1163 | G78: 16.6295 | H78: 0.9536 | I78: 5.4366 | J78: 4.727 | K78: 0.0031 | L78: 4.9094 | M78: 8.6696 | N78: 1.5394 | O78: 0.6576 | P78: 0.0065 | Q78: 77.1502 | R78: =FALSE() | S78: =FALSE() | T78: =FALSE() | U78: =FALSE()
A79: 2018 | B79: 3 | C79: =FALSE() | D79: 1.854 | E79: 0.323 | F79: 29.0572 | G79: 17.2475 | H79: 0.8909 | I79: 5.547 | J79: 5.018 | K79: 0.0011 | L79: 4.481 | M79: 8.8261 | N79: 1.4926 | O79: 0.5307 | P79: 0.011 | Q79: 75.2801 | R79: =FALSE() | S79: =FALSE() | T79: =FALSE() | U79: =FALSE()
A80: 2018 | B80: 4 | C80: =FALSE() | D80: 5.056 | E80: 0.4707 | F80: 33.4145 | G80: 14.5424 | H80: 2.0343 | I80: 9.8375 | J80: 8.8532 | K80: 0.0019 | L80: 1.4849 | M80: 9.8298 | N80: 1.4974 | O80: 0.5645 | P80: 0.0149 | Q80: 87.6019 | R80: =FALSE() | S80: =FALSE() | T80: =FALSE() | U80: =FALSE()
A81: 2019 | B81: 1 | C81: =FALSE() | D81: 3.0555 | E81: 0.5844 | F81: 36.8988 | G81: 13.9059 | H81: 1.8913 | I81: 9.8363 | J81: 8.6 | K81: 0.0032 | L81: 1.9178 | M81: 8.9751 | N81: 1.8988 | O81: 0.5635 | P81: 0.0186 | Q81: 88.1492 | R81: =FALSE() | S81: =FALSE() | T81: =FALSE() | U81: =FALSE()
A82: 2019 | B82: 2 | C82: =FALSE() | D82: 0.4624 | E82: 0.5746 | F82: 33.4341 | G82: 13.0668 | H82: 0.8318 | I82: 6.0517 | J82: 5.9362 | K82: 0.0039 | L82: 4.6208 | M82: 9.1203 | N82: 1.8081 | O82: 0.3385 | P82: 0.0175 | Q82: 76.2666 | R82: =FALSE() | S82: =FALSE() | T82: =FALSE() | U82: =FALSE()
A83: 2019 | B83: 3 | C83: =FALSE() | D83: 0.7323 | E83: 0.4704 | F83: 28.867 | G83: 13.5927 | H83: 1.4061 | I83: 6.7959 | J83: 7.1883 | K83: 0.004 | L83: 4.4883 | M83: 9.087 | N83: 1.8016 | O83: 0.3709 | P83: 0.0189 | Q83: 74.8234 | R83: =FALSE() | S83: =FALSE() | T83: =FALSE() | U83: =FALSE()
...

Sheet Capacity (MW)
A1: UK Installed Nameplate Capacity by Fuel (MW) - Quarterly, All Generating Companies
A2: Sources: DUKES 5.7 (thermal/nuclear, de-rated NOT applied to these fuels) + DUKES 6.2 (wind/solar/marine/hydro, nameplate not de-rated). See Cover sheet - important correction explained there.
A4: Year | B4: Quarter | C4: Coal | D4: Oil | E4: Gas | F4: Nuclear | G4: Hydro (natural flow) | H4: Onshore wind | I4: Offshore wind | J4: Shoreline wave / tidal | K4: Solar | L4: Bioenergy | M4: Other fuels | N4: Pumped storage | O4: Battery storage | P4: Total capacity | Q4: Capacity forward filled (2025-26)
A5: 2000 | B5: 1 | C5: 25428.42 | D5: 4331.96 | E5: 23257.99 | F5: 12486 | G5: 1602.56 | H5: 431.33 | I5: 3.8 | J5: 0.5 | K5: 1.93 | L5: 776.08 | M5: 7709.43 | N5: 2788 | O5: [x] | P5: 78450.511 | Q5: =FALSE()
A6: 2000 | B6: 2 | C6: 25428.42 | D6: 4331.96 | E6: 23257.99 | F6: 12486 | G6: 1602.56 | H6: 431.33 | I6: 3.8 | J6: 0.5 | K6: 1.93 | L6: 776.08 | M6: 7709.43 | N6: 2788 | O6: [x] | P6: 78450.511 | Q6: =FALSE()
A7: 2000 | B7: 3 | C7: 25428.42 | D7: 4331.96 | E7: 23257.99 | F7: 12486 | G7: 1602.56 | H7: 431.33 | I7: 3.8 | J7: 0.5 | K7: 1.93 | L7: 776.08 | M7: 7709.43 | N7: 2788 | O7: [x] | P7: 78450.511 | Q7: =FALSE()
A8: 2000 | B8: 4 | C8: 25428.42 | D8: 4331.96 | E8: 23257.99 | F8: 12486 | G8: 1602.56 | H8: 431.33 | I8: 3.8 | J8: 0.5 | K8: 1.93 | L8: 776.08 | M8: 7709.43 | N8: 2788 | O8: [x] | P8: 78450.511 | Q8: =FALSE()
A9: 2001 | B9: 1 | C9: 25519.25 | D9: 4325.4 | E9: 24277.96 | F9: 12486 | G9: 1628.7 | H9: 489.54 | I9: 3.8 | J9: 0.5 | K9: 2.75 | L9: 799.09 | M9: 7761.38 | N9: 2788 | O9: [x] | P9: 79677.87 | Q9: =FALSE()
A10: 2001 | B10: 2 | C10: 25519.25 | D10: 4325.4 | E10: 24277.96 | F10: 12486 | G10: 1628.7 | H10: 489.54 | I10: 3.8 | J10: 0.5 | K10: 2.75 | L10: 799.09 | M10: 7761.38 | N10: 2788 | O10: [x] | P10: 79677.87 | Q10: =FALSE()
A11: 2001 | B11: 3 | C11: 25519.25 | D11: 4325.4 | E11: 24277.96 | F11: 12486 | G11: 1628.7 | H11: 489.54 | I11: 3.8 | J11: 0.5 | K11: 2.75 | L11: 799.09 | M11: 7761.38 | N11: 2788 | O11: [x] | P11: 79677.87 | Q11: =FALSE()
A12: 2001 | B12: 4 | C12: 25519.25 | D12: 4325.4 | E12: 24277.96 | F12: 12486 | G12: 1628.7 | H12: 489.54 | I12: 3.8 | J12: 0.5 | K12: 2.75 | L12: 799.09 | M12: 7761.38 | N12: 2788 | O12: [x] | P12: 79677.87 | Q12: =FALSE()
A13: 2002 | B13: 1 | C13: 23126.44 | D13: 3657.07 | E13: 24577.31 | F13: 12240 | G13: 1583.05 | H13: 530.64 | I13: 3.8 | J13: 0.5 | K13: 4.14 | L13: 880.52 | M13: 7738.78 | N13: 2788 | O13: [x] | P13: 76704.819 | Q13: =FALSE()
A14: 2002 | B14: 2 | C14: 23126.44 | D14: 3657.07 | E14: 24577.31 | F14: 12240 | G14: 1583.05 | H14: 530.64 | I14: 3.8 | J14: 0.5 | K14: 4.14 | L14: 880.52 | M14: 7738.78 | N14: 2788 | O14: [x] | P14: 76704.819 | Q14: =FALSE()
A15: 2002 | B15: 3 | C15: 23126.44 | D15: 3657.07 | E15: 24577.31 | F15: 12240 | G15: 1583.05 | H15: 530.64 | I15: 3.8 | J15: 0.5 | K15: 4.14 | L15: 880.52 | M15: 7738.78 | N15: 2788 | O15: [x] | P15: 76704.819 | Q15: =FALSE()
A16: 2002 | B16: 4 | C16: 23126.44 | D16: 3657.07 | E16: 24577.31 | F16: 12240 | G16: 1583.05 | H16: 530.64 | I16: 3.8 | J16: 0.5 | K16: 4.14 | L16: 880.52 | M16: 7738.78 | N16: 2788 | O16: [x] | P16: 76704.819 | Q16: =FALSE()
... A104: 2024 | B104: 4 | C104: 18.476299 | D104: 1253.1276 | E104: 34739.539 | F104: 5883 | G104: 1898.806 | H104: 16166.23 | I104: 15836.05 | J104: 7.7 | K104: 18279.9 | L104: 8264.9745 | M104: 239.0095 | N104: 2744 | O104: [x] | P104: 71676.8 | Q104: =FALSE()
A105: 2025 | B105: 1 | C105: 18.476299 | D105: 1253.1276 | E105: 34739.539 | F105: 5883 | G105: 1898.806 | H105: 16166.23 | I105: 15836.05 | J105: 7.7 | K105: 18279.9 | L105: 8264.9745 | M105: 239.0095 | N105: 2744 | O105: [x] | P105: 71676.8 | Q105: =TRUE()
A106: 2025 | B106: 2 | C106: 18.476299 | D106: 1253.1276 | E106: 34739.539 | F106: 5883 | G106: 1898.806 | H106: 16166.23 | I106: 15836.05 | J106: 7.7 | K106: 18279.9 | L106: 8264.9745 | M106: 239.0095 | N106: 2744 | O106: [x] | P106: 71676.8 | Q106: =TRUE()
A107: 2025 | B107: 3 | C107: 18.476299 | D107: 1253.1276 | E107: 34739.539 | F107: 5883 | G107: 1898.806 | H107: 16166.23 | I107: 15836.05 | J107: 7.7 | K107: 18279.9 | L107: 8264.9745 | M107: 239.0095 | N107: 2744 | O107: [x] | P107: 71676.8 | Q107: =TRUE()
A108: 2025 | B108: 4 | C108: 18.476299 | D108: 1253.1276 | E108: 34739.539 | F108: 5883 | G108: 1898.806 | H108: 16166.23 | I108: 15836.05 | J108: 7.7 | K108: 18279.9 | L108: 8264.9745 | M108: 239.0095 | N108: 2744 | O108: [x] | P108: 71676.8 | Q108: =TRUE()
A109: 2026 | B109: 1 | C109: 18.476299 | D109: 1253.1276 | E109: 34739.539 | F109: 5883 | G109: 1898.806 | H109: 16166.23 | I109: 15836.05 | J109: 7.7 | K109: 18279.9 | L109: 8264.9745 | M109: 239.0095 | N109: 2744 | O109: [x] | P109: 71676.8 | Q109: =TRUE()
A111: Amber cells = 2025-26 forward-filled from 2024 DUKES figures. See Cover sheet for the de-rated-vs-nameplate correction and the 2024 coal caveat.

Sheet Capacity Factor (%)
A1: UK Capacity Factor by Fuel (%) - Quarterly, All Generating Companies
A2: Live formula: Capacity Factor = Generation (TWh) x 1,000,000 / (Capacity (MW) x hours in quarter). "n/a" where capacity unavailable. See Cover sheet for 2024 coal and "Other fuels" caveats.
A4: Year | B4: Quarter | C4: Hours in quarter | D4: Coal | E4: Oil | F4: Gas | G4: Nuclear | H4: Hydro (natural flow) | I4: Onshore wind | J4: Offshore wind | K4: Shoreline wave / tidal | L4: Solar | M4: Bioenergy | N4: Other fuels | O4: Pumped storage | P4: Battery storage
A5: 2000 | B5: 1 | C5: 2184 | D5: =IFERROR(IF(OR(ISTEXT('Capacity (MW)'!C5),'Capacity (MW)'!C5=0,ISTEXT('Generation (TWh)'!D5)),"n/a",'Generation (TWh)'!D5*1000000/('Capacity (MW)'!C5*$C5)),"n/a") | E5: =IFERROR(IF(OR(ISTEXT('Capacity (MW)'!D5),'Capacity (MW)'!D5=0,ISTEXT('Generation (TWh)'!E5)),"n/a",'Generation (TWh)'!E5*1000000/('Capacity (MW)'!D5*$C5)),"n/a") | F5: =IFERROR(IF(OR(ISTEXT('Capacity (MW)'!E5),'Capacity (MW)'!E5=0,ISTEXT('Generation (TWh)'!F5)),"n/a",'Generation (TWh)'!F5*1000000/('Capacity (MW)'!E5*$C5)),"n/a") | G5: =IFERROR(IF(OR(ISTEXT('Capacity (MW)'!F5),'Capacity (MW)'!F5=0,ISTEXT('Generation (TWh)'!G5)),"n/a",'Generation (TWh)'!G5*1000000/('Capacity (MW)'!F5*$C5)),"n/a") | H5: =IFERROR(IF(OR(ISTEXT('Capacity (MW)'!G5),'Capacity (MW)'!G5=0,ISTEXT('Generation (TWh)'!H5)),"n/a",'Generation (TWh)'!H5*1000000/('Capacity (MW)'!G5*$C5)),"n/a") | I5: =IFERROR(IF(OR(ISTEXT('Capacity (MW)'!H5),'Capacity (MW)'!H5=0,ISTEXT('Generation (TWh)'!I5)),"n/a",'Generation (TWh)'!I5*1000000/('Capacity (MW)'!H5*$C5)),"n/a") | J5: =IFERROR(IF(OR(ISTEXT('Capacity (MW)'!I5),'Capacity (MW)'!I5=0,ISTEXT('Generation (TWh)'!J5)),"n/a",'Generation (TWh)'!J5*1000000/('Capacity (MW)'!I5*$C5)),"n/a") | K5: =IFERROR(IF(OR(ISTEXT('Capacity (MW)'!J5),'Capacity (MW)'!J5=0,ISTEXT('Generation (TWh)'!K5)),"n/a",'Generation (TWh)'!K5*1000000/('Capacity (MW)'!J5*$C5)),"n/a") | ... P5: =IFERROR(IF(OR(ISTEXT('Capacity (MW)'!O5),'Capacity (MW)'!O5=0,ISTEXT('Generation (TWh)'!P5)),"n/a",'Generation (TWh)'!P5*1000000/('Capacity (MW)'!O5*$C5)),"n/a")
A6: 2000 | B6: 2 | C6: 2184 | D6: =IFERROR(IF(OR(ISTEXT('Capacity (MW)'!C6),'Capacity (MW)'!C6=0,ISTEXT('Generation (TWh)'!D6)),"n/a",'Generation (TWh)'!D6*1000000/('Capacity (MW)'!C6*$C6)),"n/a") | E6: =IFERROR(IF(OR(ISTEXT('Capacity (MW)'!D6),'Capacity (MW)'!D6=0,ISTEXT('Generation (TWh)'!E6)),"n/a",'Generation (TWh)'!E6*1000000/('Capacity (MW)'!D6*$C6)),"n/a") | F6: =IFERROR(IF(OR(ISTEXT('Capacity (MW)'!E6),'Capacity (MW)'!E6=0,ISTEXT('Generation (TWh)'!F6)),"n/a",'Generation (TWh)'!F6*1000000/('Capacity (MW)'!E6*$C6)),"n/a") | G6: =IFERROR(IF(OR(ISTEXT('Capacity (MW)'!F6),'Capacity (MW)'!F6=0,ISTEXT('Generation (TWh)'!G6)),"n/a",'Generation (TWh)'!G6*1000000/('Capacity (MW)'!F6*$C6)),"n/a") | H6: =IFERROR(IF(OR(ISTEXT('Capacity (MW)'!G6),'Capacity (MW)'!G6=0,ISTEXT('Generation (TWh)'!H6)),"n/a",'Generation (TWh)'!H6*1000000/('Capacity (MW)'!G6*$C6)),"n/a") | I6: =IFERROR(IF(OR(ISTEXT('Capacity (MW)'!H6),'Capacity (MW)'!H6=0,ISTEXT('Generation (TWh)'!I6)),"n/a",'Generation (TWh)'!I6*1000000/('Capacity (MW)'!H6*$C6)),"n/a") | J6: =IFERROR(IF(OR(ISTEXT('Capacity (MW)'!I6),'Capacity (MW)'!I6=0,ISTEXT('Generation (TWh)'!J6)),"n/a",'Generation (TWh)'!J6*1000000/('Capacity (MW)'!I6*$C6)),"n/a") | K6: =IFERROR(IF(OR(ISTEXT('Capacity (MW)'!J6),'Capacity (MW)'!J6=0,ISTEXT('Generation (TWh)'!K6)),"n/a",'Generation (TWh)'!K6*1000000/('Capacity (MW)'!J6*$C6)),"n/a") | ... P6: =IFERROR(IF(OR(ISTEXT('Capacity (MW)'!O6),'Capacity (MW)'!O6=0,ISTEXT('Generation (TWh)'!P6)),"n/a",'Generation (TWh)'!P6*1000000/('Capacity (MW)'!O6*$C6)),"n/a")
A7: 2000 | B7: 3 | C7: 2208 | D7: =IFERROR(IF(OR(ISTEXT('Capacity (MW)'!C7),'Capacity (MW)'!C7=0,ISTEXT('Generation (TWh)'!D7)),"n/a",'Generation (TWh)'!D7*1000000/('Capacity (MW)'!C7*$C7)),"n/a") | E7: =IFERROR(IF(OR(ISTEXT('Capacity (MW)'!D7),'Capacity (MW)'!D7=0,ISTEXT('Generation (TWh)'!E7)),"n/a",'Generation (TWh)'!E7*1000000/('Capacity (MW)'!D7*$C7)),"n/a") | F7: =IFERROR(IF(OR(ISTEXT('Capacity (MW)'!E7),'Capacity (MW)'!E7=0,ISTEXT('Generation (TWh)'!F7)),"n/a",'Generation (TWh)'!F7*1000000/('Capacity (MW)'!E7*$C7)),"n/a") | G7: =IFERROR(IF(OR(ISTEXT('Capacity (MW)'!F7),'Capacity (MW)'!F7=0,ISTEXT('Generation (TWh)'!G7)),"n/a",'Generation (TWh)'!G7*1000000/('Capacity (MW)'!F7*$C7)),"n/a") | H7: =IFERROR(IF(OR(ISTEXT('Capacity (MW)'!G7),'Capacity (MW)'!G7=0,ISTEXT('Generation (TWh)'!H7)),"n/a",'Generation (TWh)'!H7*1000000/('Capacity (MW)'!G7*$C7)),"n/a") | I7: =IFERROR(IF(OR(ISTEXT('Capacity (MW)'!H7),'Capacity (MW)'!H7=0,ISTEXT('Generation (TWh)'!I7)),"n/a",'Generation (TWh)'!I7*1000000/('Capacity (MW)'!H7*$C7)),"n/a") | J7: =IFERROR(IF(OR(ISTEXT('Capacity (MW)'!I7),'Capacity (MW)'!I7=0,ISTEXT('Generation (TWh)'!J7)),"n/a",'Generation (TWh)'!J7*1000000/('Capacity (MW)'!I7*$C7)),"n/a") | K7: =IFERROR(IF(OR(ISTEXT('Capacity (MW)'!J7),'Capacity (MW)'!J7=0,ISTEXT('Generation (TWh)'!K7)),"n/a",'Generation (TWh)'!K7*1000000/('Capacity (MW)'!J7*$C7)),"n/a") | ... P7: =IFERROR(IF(OR(ISTEXT('Capacity (MW)'!O7),'Capacity (MW)'!O7=0,ISTEXT('Generation (TWh)'!P7)),"n/a",'Generation (TWh)'!P7*1000000/('Capacity (MW)'!O7*$C7)),"n/a")
A8: 2000 | B8: 4 | C8: 2208 | D8: =IFERROR(IF(OR(ISTEXT('Capacity (MW)'!C8),'Capacity (MW)'!C8=0,ISTEXT('Generation (TWh)'!D8)),"n/a",'Generation (TWh)'!D8*1000000/('Capacity (MW)'!C8*$C8)),"n/a") | E8: =IFERROR(IF(OR(ISTEXT('Capacity (MW)'!D8),'Capacity (MW)'!D8=0,ISTEXT('Generation (TWh)'!E8)),"n/a",'Generation (TWh)'!E8*1000000/('Capacity (MW)'!D8*$C8)),"n/a") | F8: =IFERROR(IF(OR(ISTEXT('Capacity (MW)'!E8),'Capacity (MW)'!E8=0,ISTEXT('Generation (TWh)'!F8)),"n/a",'Generation (TWh)'!F8*1000000/('Capacity (MW)'!E8*$C8)),"n/a") | G8: =IFERROR(IF(OR(ISTEXT('Capacity (MW)'!F8),'Capacity (MW)'!F8=0,ISTEXT('Generation (TWh)'!G8)),"n/a",'Generation (TWh)'!G8*1000000/('Capacity (MW)'!F8*$C8)),"n/a") | H8: =IFERROR(IF(OR(ISTEXT('Capacity (MW)'!G8),'Capacity (MW)'!G8=0,ISTEXT('Generation (TWh)'!H8)),"n/a",'Generation (TWh)'!H8*1000000/('Capacity (MW)'!G8*$C8)),"n/a") | I8: =IFERROR(IF(OR(ISTEXT('Capacity (MW)'!H8),'Capacity (MW)'!H8=0,ISTEXT('Generation (TWh)'!I8)),"n/a",'Generation (TWh)'!I8*1000000/('Capacity (MW)'!H8*$C8)),"n/a") | J8: =IFERROR(IF(OR(ISTEXT('Capacity (MW)'!I8),'Capacity (MW)'!I8=0,ISTEXT('Generation (TWh)'!J8)),"n/a",'Generation (TWh)'!J8*1000000/('Capacity (MW)'!I8*$C8)),"n/a") | K8: =IFERROR(IF(OR(ISTEXT('Capacity (MW)'!J8),'Capacity (MW)'!J8=0,ISTEXT('Generation (TWh)'!K8)),"n/a",'Generation (TWh)'!K8*1000000/('Capacity (MW)'!J8*$C8)),"n/a") | ... P8: =IFERROR(IF(OR(ISTEXT('Capacity (MW)'!O8),'Capacity (MW)'!O8=0,ISTEXT('Generation (TWh)'!P8)),"n/a",'Generation (TWh)'!P8*1000000/('Capacity (MW)'!O8*$C8)),"n/a")
A9: 2001 | B9: 1 | C9: 2160 | D9: =IFERROR(IF(OR(ISTEXT('Capacity (MW)'!C9),'Capacity (MW)'!C9=0,ISTEXT('Generation (TWh)'!D9)),"n/a",'Generation (TWh)'!D9*1000000/('Capacity (MW)'!C9*$C9)),"n/a") | E9: =IFERROR(IF(OR(ISTEXT('Capacity (MW)'!D9),'Capacity (MW)'!D9=0,ISTEXT('Generation (TWh)'!E9)),"n/a",'Generation (TWh)'!E9*1000000/('Capacity (MW)'!D9*$C9)),"n/a") | F9: =IFERROR(IF(OR(ISTEXT('Capacity (MW)'!E9),'Capacity (MW)'!E9=0,ISTEXT('Generation (TWh)'!F9)),"n/a",'Generation (TWh)'!F9*1000000/('Capacity (MW)'!E9*$C9)),"n/a") | G9: =IFERROR(IF(OR(ISTEXT('Capacity (MW)'!F9),'Capacity (MW)'!F9=0,ISTEXT('Generation (TWh)'!G9)),"n/a",'Generation (TWh)'!G9*1000000/('Capacity (MW)'!F9*$C9)),"n/a") | H9: =IFERROR(IF(OR(ISTEXT('Capacity (MW)'!G9),'Capacity (MW)'!G9=0,ISTEXT('Generation (TWh)'!H9)),"n/a",'Generation (TWh)'!H9*1000000/('Capacity (MW)'!G9*$C9)),"n/a") | I9: =IFERROR(IF(OR(ISTEXT('Capacity (MW)'!H9),'Capacity (MW)'!H9=0,ISTEXT('Generation (TWh)'!I9)),"n/a",'Generation (TWh)'!I9*1000000/('Capacity (MW)'!H9*$C9)),"n/a") | J9: =IFERROR(IF(OR(ISTEXT('Capacity (MW)'!I9),'Capacity (MW)'!I9=0,ISTEXT('Generation (TWh)'!J9)),"n/a",'Generation (TWh)'!J9*1000000/('Capacity (MW)'!I9*$C9)),"n/a") | K9: =IFERROR(IF(OR(ISTEXT('Capacity (MW)'!J9),'Capacity (MW)'!J9=0,ISTEXT('Generation (TWh)'!K9)),"n/a",'Generation (TWh)'!K9*1000000/('Capacity (MW)'!J9*$C9)),"n/a") | ... P9: =IFERROR(IF(OR(ISTEXT('Capacity (MW)'!O9),'Capacity (MW)'!O9=0,ISTEXT('Generation (TWh)'!P9)),"n/a",'Generation (TWh)'!P9*1000000/('Capacity (MW)'!O9*$C9)),"n/a")
A10: 2001 | B10: 2 | C10: 2184 | D10: =IFERROR(IF(OR(ISTEXT('Capacity (MW)'!C10),'Capacity (MW)'!C10=0,ISTEXT('Generation (TWh)'!D10)),"n/a",'Generation (TWh)'!D10*1000000/('Capacity (MW)'!C10*$C10)),"n/a") | E10: =IFERROR(IF(OR(ISTEXT('Capacity (MW)'!D10),'Capacity (MW)'!D10=0,ISTEXT('Generation (TWh)'!E10)),"n/a",'Generation (TWh)'!E10*1000000/('Capacity (MW)'!D10*$C10)),"n/a") | F10: =IFERROR(IF(OR(ISTEXT('Capacity (MW)'!E10),'Capacity (MW)'!E10=0,ISTEXT('Generation (TWh)'!F10)),"n/a",'Generation (TWh)'!F10*1000000/('Capacity (MW)'!E10*$C10)),"n/a") | G10: =IFERROR(IF(OR(ISTEXT('Capacity (MW)'!F10),'Capacity (MW)'!F10=0,ISTEXT('Generation (TWh)'!G10)),"n/a",'Generation (TWh)'!G10*1000000/('Capacity (MW)'!F10*$C10)),"n/a") | H10: =IFERROR(IF(OR(ISTEXT('Capacity (MW)'!G10),'Capacity (MW)'!G10=0,ISTEXT('Generation (TWh)'!H10)),"n/a",'Generation (TWh)'!H10*1000000/('Capacity (MW)'!G10*$C10)),"n/a") | I10: =IFERROR(IF(OR(ISTEXT('Capacity (MW)'!H10),'Capacity (MW)'!H10=0,ISTEXT('Generation (TWh)'!I10)),"n/a",'Generation (TWh)'!I10*1000000/('Capacity (MW)'!H10*$C10)),"n/a") | J10: =IFERROR(IF(OR(ISTEXT('Capacity (MW)'!I10),'Capacity (MW)'!I10=0,ISTEXT('Generation (TWh)'!J10)),"n/a",'Generation (TWh)'!J10*1000000/('Capacity (MW)'!I10*$C10)),"n/a") | K10: =IFERROR(IF(OR(ISTEXT('Capacity (MW)'!J10),'Capacity (MW)'!J10=0,ISTEXT('Generation (TWh)'!K10)),"n/a",'Generation (TWh)'!K10*1000000/('Capacity (MW)'!J10*$C10)),"n/a") | ... P10: =IFERROR(IF(OR(ISTEXT('Capacity (MW)'!O10),'Capacity (MW)'!O10=0,ISTEXT('Generation (TWh)'!P10)),"n/a",'Generation (TWh)'!P10*1000000/('Capacity (MW)'!O10*$C10)),"n/a")
A11: 2001 | B11: 3 | C11: 2208 | D11: =IFERROR(IF(OR(ISTEXT('Capacity (MW)'!C11),'Capacity (MW)'!C11=0,ISTEXT('Generation (TWh)'!D11)),"n/a",'Generation (TWh)'!D11*1000000/('Capacity (MW)'!C11*$C11)),"n/a") | E11: =IFERROR(IF(OR(ISTEXT('Capacity (MW)'!D11),'Capacity (MW)'!D11=0,ISTEXT('Generation (TWh)'!E11)),"n/a",'Generation (TWh)'!E11*1000000/('Capacity (MW)'!D11*$C11)),"n/a") | F11: =IFERROR(IF(OR(ISTEXT('Capacity (MW)'!E11),'Capacity (MW)'!E11=0,ISTEXT('Generation (TWh)'!F11)),"n/a",'Generation (TWh)'!F11*1000000/('Capacity (MW)'!E11*$C11)),"n/a") | G11: =IFERROR(IF(OR(ISTEXT('Capacity (MW)'!F11),'Capacity (MW)'!F11=0,ISTEXT('Generation (TWh)'!G11)),"n/a",'Generation (TWh)'!G11*1000000/('Capacity (MW)'!F11*$C11)),"n/a") | H11: =IFERROR(IF(OR(ISTEXT('Capacity (MW)'!G11),'Capacity (MW)'!G11=0,ISTEXT('Generation (TWh)'!H11)),"n/a",'Generation (TWh)'!H11*1000000/('Capacity (MW)'!G11*$C11)),"n/a") | I11: =IFERROR(IF(OR(ISTEXT('Capacity (MW)'!H11),'Capacity (MW)'!H11=0,ISTEXT('Generation (TWh)'!I11)),"n/a",'Generation (TWh)'!I11*1000000/('Capacity (MW)'!H11*$C11)),"n/a") | J11: =IFERROR(IF(OR(ISTEXT('Capacity (MW)'!I11),'Capacity (MW)'!I11=0,ISTEXT('Generation (TWh)'!J11)),"n/a",'Generation (TWh)'!J11*1000000/('Capacity (MW)'!I11*$C11)),"n/a") | K11: =IFERROR(IF(OR(ISTEXT('Capacity (MW)'!J11),'Capacity (MW)'!J11=0,ISTEXT('Generation (TWh)'!K11)),"n/a",'Generation (TWh)'!K11*1000000/('Capacity (MW)'!J11*$C11)),"n/a") | ... P11: =IFERROR(IF(OR(ISTEXT('Capacity (MW)'!O11),'Capacity (MW)'!O11=0,ISTEXT('Generation (TWh)'!P11)),"n/a",'Generation (TWh)'!P11*1000000/('Capacity (MW)'!O11*$C11)),"n/a")
A12: 2001 | B12: 4 | C12: 2208 | D12: =IFERROR(IF(OR(ISTEXT('Capacity (MW)'!C12),'Capacity (MW)'!C12=0,ISTEXT('Generation (TWh)'!D12)),"n/a",'Generation (TWh)'!D12*1000000/('Capacity (MW)'!C12*$C12)),"n/a") | E12: =IFERROR(IF(OR(ISTEXT('Capacity (MW)'!D12),'Capacity (MW)'!D12=0,ISTEXT('Generation (TWh)'!E12)),"n/a",'Generation (TWh)'!E12*1000000/('Capacity (MW)'!D12*$C12)),"n/a") | F12: =IFERROR(IF(OR(ISTEXT('Capacity (MW)'!E12),'Capacity (MW)'!E12=0,ISTEXT('Generation (TWh)'!F12)),"n/a",'Generation (TWh)'!F12*1000000/('Capacity (MW)'!E12*$C12)),"n/a") | G12: =IFERROR(IF(OR(ISTEXT('Capacity (MW)'!F12),'Capacity (MW)'!F12=0,ISTEXT('Generation (TWh)'!G12)),"n/a",'Generation (TWh)'!G12*1000000/('Capacity (MW)'!F12*$C12)),"n/a") | H12: =IFERROR(IF(OR(ISTEXT('Capacity (MW)'!G12),'Capacity (MW)'!G12=0,ISTEXT('Generation (TWh)'!H12)),"n/a",'Generation (TWh)'!H12*1000000/('Capacity (MW)'!G12*$C12)),"n/a") | I12: =IFERROR(IF(OR(ISTEXT('Capacity (MW)'!H12),'Capacity (MW)'!H12=0,ISTEXT('Generation (TWh)'!I12)),"n/a",'Generation (TWh)'!I12*1000000/('Capacity (MW)'!H12*$C12)),"n/a") | J12: =IFERROR(IF(OR(ISTEXT('Capacity (MW)'!I12),'Capacity (MW)'!I12=0,ISTEXT('Generation (TWh)'!J12)),"n/a",'Generation (TWh)'!J12*1000000/('Capacity (MW)'!I12*$C12)),"n/a") | K12: =IFERROR(IF(OR(ISTEXT('Capacity (MW)'!J12),'Capacity (MW)'!J12=0,ISTEXT('Generation (TWh)'!K12)),"n/a",'Generation (TWh)'!K12*1000000/('Capacity (MW)'!J12*$C12)),"n/a") | ... P12: =IFERROR(IF(OR(ISTEXT('Capacity (MW)'!O12),'Capacity (MW)'!O12=0,ISTEXT('Generation (TWh)'!P12)),"n/a",'Generation (TWh)'!P12*1000000/('Capacity (MW)'!O12*$C12)),"n/a")
A13: 2002 | B13: 1 | C13: 2160 | D13: =IFERROR(IF(OR(ISTEXT('Capacity (MW)'!C13),'Capacity (MW)'!C13=0,ISTEXT('Generation (TWh)'!D13)),"n/a",'Generation (TWh)'!D13*1000000/('Capacity (MW)'!C13*$C13)),"n/a") | E13: =IFERROR(IF(OR(ISTEXT('Capacity (MW)'!D13),'Capacity (MW)'!D13=0,ISTEXT('Generation (TWh)'!E13)),"n/a",'Generation (TWh)'!E13*1000000/('Capacity (MW)'!D13*$C13)),"n/a") | F13: =IFERROR(IF(OR(ISTEXT('Capacity (MW)'!E13),'Capacity (MW)'!E13=0,ISTEXT('Generation (TWh)'!F13)),"n/a",'Generation (TWh)'!F13*1000000/('Capacity (MW)'!E13*$C13)),"n/a") | G13: =IFERROR(IF(OR(ISTEXT('Capacity (MW)'!F13),'Capacity (MW)'!F13=0,ISTEXT('Generation (TWh)'!G13)),"n/a",'Generation (TWh)'!G13*1000000/('Capacity (MW)'!F13*$C13)),"n/a") | H13: =IFERROR(IF(OR(ISTEXT('Capacity (MW)'!G13),'Capacity (MW)'!G13=0,ISTEXT('Generation (TWh)'!H13)),"n/a",'Generation (TWh)'!H13*1000000/('Capacity (MW)'!G13*$C13)),"n/a") | I13: =IFERROR(IF(OR(ISTEXT('Capacity (MW)'!H13),'Capacity (MW)'!H13=0,ISTEXT('Generation (TWh)'!I13)),"n/a",'Generation (TWh)'!I13*1000000/('Capacity (MW)'!H13*$C13)),"n/a") | J13: =IFERROR(IF(OR(ISTEXT('Capacity (MW)'!I13),'Capacity (MW)'!I13=0,ISTEXT('Generation (TWh)'!J13)),"n/a",'Generation (TWh)'!J13*1000000/('Capacity (MW)'!I13*$C13)),"n/a") | K13: =IFERROR(IF(OR(ISTEXT('Capacity (MW)'!J13),'Capacity (MW)'!J13=0,ISTEXT('Generation (TWh)'!K13)),"n/a",'Generation (TWh)'!K13*1000000/('Capacity (MW)'!J13*$C13)),"n/a") | ... P13: =IFERROR(IF(OR(ISTEXT('Capacity (MW)'!O13),'Capacity (MW)'!O13=0,ISTEXT('Generation (TWh)'!P13)),"n/a",'Generation (TWh)'!P13*1000000/('Capacity (MW)'!O13*$C13)),"n/a")
A14: 2002 | B14: 2 | C14: 2184 | D14: =IFERROR(IF(OR(ISTEXT('Capacity (MW)'!C14),'Capacity (MW)'!C14=0,ISTEXT('Generation (TWh)'!D14)),"n/a",'Generation (TWh)'!D14*1000000/('Capacity (MW)'!C14*$C14)),"n/a") | E14: =IFERROR(IF(OR(ISTEXT('Capacity (MW)'!D14),'Capacity (MW)'!D14=0,ISTEXT('Generation (TWh)'!E14)),"n/a",'Generation (TWh)'!E14*1000000/('Capacity (MW)'!D14*$C14)),"n/a") | F14: =IFERROR(IF(OR(ISTEXT('Capacity (MW)'!E14),'Capacity (MW)'!E14=0,ISTEXT('Generation (TWh)'!F14)),"n/a",'Generation (TWh)'!F14*1000000/('Capacity (MW)'!E14*$C14)),"n/a") | G14: =IFERROR(IF(OR(ISTEXT('Capacity (MW)'!F14),'Capacity (MW)'!F14=0,ISTEXT('Generation (TWh)'!G14)),"n/a",'Generation (TWh)'!G14*1000000/('Capacity (MW)'!F14*$C14)),"n/a") | H14: =IFERROR(IF(OR(ISTEXT('Capacity (MW)'!G14),'Capacity (MW)'!G14=0,ISTEXT('Generation (TWh)'!H14)),"n/a",'Generation (TWh)'!H14*1000000/('Capacity (MW)'!G14*$C14)),"n/a") | I14: =IFERROR(IF(OR(ISTEXT('Capacity (MW)'!H14),'Capacity (MW)'!H14=0,ISTEXT('Generation (TWh)'!I14)),"n/a",'Generation (TWh)'!I14*1000000/('Capacity (MW)'!H14*$C14)),"n/a") | J14: =IFERROR(IF(OR(ISTEXT('Capacity (MW)'!I14),'Capacity (MW)'!I14=0,ISTEXT('Generation (TWh)'!J14)),"n/a",'Generation (TWh)'!J14*1000000/('Capacity (MW)'!I14*$C14)),"n/a") | K14: =IFERROR(IF(OR(ISTEXT('Capacity (MW)'!J14),'Capacity (MW)'!J14=0,ISTEXT('Generation (TWh)'!K14)),"n/a",'Generation (TWh)'!K14*1000000/('Capacity (MW)'!J14*$C14)),"n/a") | ... P14: =IFERROR(IF(OR(ISTEXT('Capacity (MW)'!O14),'Capacity (MW)'!O14=0,ISTEXT('Generation (TWh)'!P14)),"n/a",'Generation (TWh)'!P14*1000000/('Capacity (MW)'!O14*$C14)),"n/a")
A15: 2002 | B15: 3 | C15: 2208 | D15: =IFERROR(IF(OR(ISTEXT('Capacity (MW)'!C15),'Capacity (MW)'!C15=0,ISTEXT('Generation (TWh)'!D15)),"n/a",'Generation (TWh)'!D15*1000000/('Capacity (MW)'!C15*$C15)),"n/a") | E15: =IFERROR(IF(OR(ISTEXT('Capacity (MW)'!D15),'Capacity (MW)'!D15=0,ISTEXT('Generation (TWh)'!E15)),"n/a",'Generation (TWh)'!E15*1000000/('Capacity (MW)'!D15*$C15)),"n/a") | F15: =IFERROR(IF(OR(ISTEXT('Capacity (MW)'!E15),'Capacity (MW)'!E15=0,ISTEXT('Generation (TWh)'!F15)),"n/a",'Generation (TWh)'!F15*1000000/('Capacity (MW)'!E15*$C15)),"n/a") | G15: =IFERROR(IF(OR(ISTEXT('Capacity (MW)'!F15),'Capacity (MW)'!F15=0,ISTEXT('Generation (TWh)'!G15)),"n/a",'Generation (TWh)'!G15*1000000/('Capacity (MW)'!F15*$C15)),"n/a") | H15: =IFERROR(IF(OR(ISTEXT('Capacity (MW)'!G15),'Capacity (MW)'!G15=0,ISTEXT('Generation (TWh)'!H15)),"n/a",'Generation (TWh)'!H15*1000000/('Capacity (MW)'!G15*$C15)),"n/a") | I15: =IFERROR(IF(OR(ISTEXT('Capacity (MW)'!H15),'Capacity (MW)'!H15=0,ISTEXT('Generation (TWh)'!I15)),"n/a",'Generation (TWh)'!I15*1000000/('Capacity (MW)'!H15*$C15)),"n/a") | J15: =IFERROR(IF(OR(ISTEXT('Capacity (MW)'!I15),'Capacity (MW)'!I15=0,ISTEXT('Generation (TWh)'!J15)),"n/a",'Generation (TWh)'!J15*1000000/('Capacity (MW)'!I15*$C15)),"n/a") | K15: =IFERROR(IF(OR(ISTEXT('Capacity (MW)'!J15),'Capacity (MW)'!J15=0,ISTEXT('Generation (TWh)'!K15)),"n/a",'Generation (TWh)'!K15*1000000/('Capacity (MW)'!J15*$C15)),"n/a") | ... P15: =IFERROR(IF(OR(ISTEXT('Capacity (MW)'!O15),'Capacity (MW)'!O15=0,ISTEXT('Generation (TWh)'!P15)),"n/a",'Generation (TWh)'!P15*1000000/('Capacity (MW)'!O15*$C15)),"n/a")
A16: 2002 | B16: 4 | C16: 2208 | D16: =IFERROR(IF(OR(ISTEXT('Capacity (MW)'!C16),'Capacity (MW)'!C16=0,ISTEXT('Generation (TWh)'!D16)),"n/a",'Generation (TWh)'!D16*1000000/('Capacity (MW)'!C16*$C16)),"n/a") | E16: =IFERROR(IF(OR(ISTEXT('Capacity (MW)'!D16),'Capacity (MW)'!D16=0,ISTEXT('Generation (TWh)'!E16)),"n/a",'Generation (TWh)'!E16*1000000/('Capacity (MW)'!D16*$C16)),"n/a") | F16: =IFERROR(IF(OR(ISTEXT('Capacity (MW)'!E16),'Capacity (MW)'!E16=0,ISTEXT('Generation (TWh)'!F16)),"n/a",'Generation (TWh)'!F16*1000000/('Capacity (MW)'!E16*$C16)),"n/a") | G16: =IFERROR(IF(OR(ISTEXT('Capacity (MW)'!F16),'Capacity (MW)'!F16=0,ISTEXT('Generation (TWh)'!G16)),"n/a",'Generation (TWh)'!G16*1000000/('Capacity (MW)'!F16*$C16)),"n/a") | H16: =IFERROR(IF(OR(ISTEXT('Capacity (MW)'!G16),'Capacity (MW)'!G16=0,ISTEXT('Generation (TWh)'!H16)),"n/a",'Generation (TWh)'!H16*1000000/('Capacity (MW)'!G16*$C16)),"n/a") | I16: =IFERROR(IF(OR(ISTEXT('Capacity (MW)'!H16),'Capacity (MW)'!H16=0,ISTEXT('Generation (TWh)'!I16)),"n/a",'Generation (TWh)'!I16*1000000/('Capacity (MW)'!H16*$C16)),"n/a") | J16: =IFERROR(IF(OR(ISTEXT('Capacity (MW)'!I16),'Capacity (MW)'!I16=0,ISTEXT('Generation (TWh)'!J16)),"n/a",'Generation (TWh)'!J16*1000000/('Capacity (MW)'!I16*$C16)),"n/a") | K16: =IFERROR(IF(OR(ISTEXT('Capacity (MW)'!J16),'Capacity (MW)'!J16=0,ISTEXT('Generation (TWh)'!K16)),"n/a",'Generation (TWh)'!K16*1000000/('Capacity (MW)'!J16*$C16)),"n/a") | ... P16: =IFERROR(IF(OR(ISTEXT('Capacity (MW)'!O16),'Capacity (MW)'!O16=0,ISTEXT('Generation (TWh)'!P16)),"n/a",'Generation (TWh)'!P16*1000000/('Capacity (MW)'!O16*$C16)),"n/a")
... A109: 2026 | B109: 1 | C109: 2160 | D109: =IFERROR(IF(OR(ISTEXT('Capacity (MW)'!C109),'Capacity (MW)'!C109=0,ISTEXT('Generation (TWh)'!D109)),"n/a",'Generation (TWh)'!D109*1000000/('Capacity (MW)'!C109*$C109)),"n/a") | E109: =IFERROR(IF(OR(ISTEXT('Capacity (MW)'!D109),'Capacity (MW)'!D109=0,ISTEXT('Generation (TWh)'!E109)),"n/a",'Generation (TWh)'!E109*1000000/('Capacity (MW)'!D109*$C109)),"n/a") | F109: =IFERROR(IF(OR(ISTEXT('Capacity (MW)'!E109),'Capacity (MW)'!E109=0,ISTEXT('Generation (TWh)'!F109)),"n/a",'Generation (TWh)'!F109*1000000/('Capacity (MW)'!E109*$C109)),"n/a") | G109: =IFERROR(IF(OR(ISTEXT('Capacity (MW)'!F109),'Capacity (MW)'!F109=0,ISTEXT('Generation (TWh)'!G109)),"n/a",'Generation (TWh)'!G109*1000000/('Capacity (MW)'!F109*$C109)),"n/a") | H109: =IFERROR(IF(OR(ISTEXT('Capacity (MW)'!G109),'Capacity (MW)'!G109=0,ISTEXT('Generation (TWh)'!H109)),"n/a",'Generation (TWh)'!H109*1000000/('Capacity (MW)'!G109*$C109)),"n/a") | I109: =IFERROR(IF(OR(ISTEXT('Capacity (MW)'!H109),'Capacity (MW)'!H109=0,ISTEXT('Generation (TWh)'!I109)),"n/a",'Generation (TWh)'!I109*1000000/('Capacity (MW)'!H109*$C109)),"n/a") | J109: =IFERROR(IF(OR(ISTEXT('Capacity (MW)'!I109),'Capacity (MW)'!I109=0,ISTEXT('Generation (TWh)'!J109)),"n/a",'Generation (TWh)'!J109*1000000/('Capacity (MW)'!I109*$C109)),"n/a") | K109: =IFERROR(IF(OR(ISTEXT('Capacity (MW)'!J109),'Capacity (MW)'!J109=0,ISTEXT('Generation (TWh)'!K109)),"n/a",'Generation (TWh)'!K109*1000000/('Capacity (MW)'!J109*$C109)),"n/a") | ... P109: =IFERROR(IF(OR(ISTEXT('Capacity (MW)'!O109),'Capacity (MW)'!O109=0,ISTEXT('Generation (TWh)'!P109)),"n/a",'Generation (TWh)'!P109*1000000/('Capacity (MW)'!O109*$C109)),"n/a")
A111: Red cells = flagged as unreliable (2024 coal capacity collapse; "Other fuels" category mismatch). See Cover sheet.
A112: Formulas reference the Generation and Capacity sheets directly - recalculates automatically if source data is edited.

Sheet Curtailment Costs (GBP)
A1: GB System Balancing Constraint Costs (GBP) - Quarterly, by Category
A2: Source: NESO "Constraint Breakdown" dataset (daily, aggregated to quarterly). Complete series, Q2 2017 to Q1 2026, no gaps. See Cover sheet.
A4: Year | B4: Quarter | C4: Total cost (GBP) | D4: Thermal constraints cost | E4: Voltage constraints cost | F4: Increasing system inertia cost | G4: Reducing largest loss cost
A5: 2017 | B5: 2 | C5: 96639084 | D5: 70605838 | E5: 9347962 | F5: 37001 | G5: 16648283
A6: 2017 | B6: 3 | C6: 99005499 | D6: 67188174 | E6: 11362939 | F6: 974626 | G6: 19479760
A7: 2017 | B7: 4 | C7: 141449810 | D7: 120416164 | E7: 5897635 | F7: 1200061 | G7: 13935950
A8: 2018 | B8: 1 | C8: 59791954 | D8: 51186029 | E8: 1703322 | F8: 526134 | G8: 6376469
A9: 2018 | B9: 2 | C9: 94027313 | D9: 64427301 | E9: 5107434 | F9: 246688 | G9: 24245890
A10: 2018 | B10: 3 | C10: 174710142 | D10: 125881585 | E10: 6077618 | F10: 1113292 | G10: 41637647
A11: 2018 | B11: 4 | C11: 185266979 | D11: 140081900 | E11: 4042812 | F11: 498770 | G11: 40643497
A12: 2019 | B12: 1 | C12: 161184352 | D12: 117801129 | E12: 8168507 | F12: 3615560 | G12: 31599156
A13: 2019 | B13: 2 | C13: 105048963 | D13: 52104517 | E13: 12276067 | F13: 2315583 | G13: 38352796
A14: 2019 | B14: 3 | C14: 139278403 | D14: 61981910 | E14: 29697961 | F14: 1115333 | G14: 46483199
A15: 2019 | B15: 4 | C15: 179690482 | D15: 116306466 | E15: 12261692 | F15: 280817 | G15: 50841507
A16: 2020 | B16: 1 | C16: 266831654 | D16: 189259707 | E16: 6039716 | F16: 1862445 | G16: 69669786
... A40: 2026 | B40: 1 | C40: 666293008 | D40: 635326343 | E40: 29689800 | F40: 1276865 | G40: 0
A42: Complete series, no gaps. Red = Q4 2021, an unusually large cost spike (£697m) - flagged, not smoothed. See Cover sheet.
